<?xml version="1.0" encoding="utf-8"?>
<!-- =================================================================================== -->
<!-- |    This document was autogenerated by xacro from gp25.xacro                     | -->
<!-- |    EDITING THIS FILE BY HAND IS NOT RECOMMENDED                                 | -->
<!-- =================================================================================== -->
<robot name="motoman_gp25" xmlns:xacro="http://ros.org/wiki/xacro">
  <!-- Properties -->
  <material name="yaskawa_blue">
    <color rgba="0.12941 0.14902 0.74902 1"/>
  </material>
  <!-- link list -->
  <link name="base_link">
    <visual>
      <geometry>
        <mesh filename="package://motoman_gp25_support/meshes/visual/base_link.stl"/>
      </geometry>
      <material name="yaskawa_blue"/>
    </visual>
    <collision>
      <geometry>
        <mesh filename="package://motoman_gp25_support/meshes/collision/base_link.stl"/>
      </geometry>
    </collision>
  </link>
  <link name="link_1_s">
    <visual>
      <geometry>
        <mesh filename="package://motoman_gp25_support/meshes/visual/link_1_s.stl"/>
      </geometry>
      <material name="yaskawa_blue"/>
    </visual>
    <collision>
      <geometry>
        <mesh filename="package://motoman_gp25_support/meshes/collision/link_1_s.stl"/>
      </geometry>
    </collision>
  </link>
  <link name="link_2_l">
    <visual>
      <geometry>
        <mesh filename="package://motoman_gp25_support/meshes/visual/link_2_l.stl"/>
      </geometry>
      <material name="yaskawa_blue"/>
    </visual>
    <collision>
      <geometry>
        <mesh filename="package://motoman_gp25_support/meshes/collision/link_2_l.stl"/>
      </geometry>
    </collision>
  </link>
  <link name="link_3_u">
    <visual>
      <geometry>
        <mesh filename="package://motoman_gp25_support/meshes/visual/link_3_u.stl"/>
      </geometry>
      <material name="yaskawa_blue"/>
    </visual>
    <collision>
      <geometry>
        <mesh filename="package://motoman_gp25_support/meshes/collision/link_3_u.stl"/>
      </geometry>
    </collision>
  </link>
  <link name="link_4_r">
    <visual>
      <geometry>
        <mesh filename="package://motoman_gp25_support/meshes/visual/link_4_r.stl"/>
      </geometry>
      <material name="yaskawa_blue"/>
    </visual>
    <collision>
      <geometry>
        <mesh filename="package://motoman_gp25_support/meshes/collision/link_4_r.stl"/>
      </geometry>
    </collision>
  </link>
  <link name="link_5_b">
    <visual>
      <geometry>
        <mesh filename="package://motoman_gp25_support/meshes/visual/link_5_b.stl"/>
      </geometry>
      <material name="yaskawa_blue"/>
    </visual>
    <collision>
      <geometry>
        <mesh filename="package://motoman_gp25_support/meshes/collision/link_5_b.stl"/>
      </geometry>
    </collision>
  </link>
  <link name="link_6_t">
    <visual>
      <geometry>
        <mesh filename="package://motoman_gp25_support/meshes/visual/link_6_t.stl"/>
      </geometry>
      <material name="yaskawa_blue"/>
    </visual>
    <collision>
      <geometry>
        <mesh filename="package://motoman_gp25_support/meshes/collision/link_6_t.stl"/>
      </geometry>
    </collision>
  </link>
  <link name="tool0"/>
  <!-- end of link list -->
  <!-- joint list -->
  <joint name="joint_1_s" type="revolute">
    <parent link="base_link"/>
    <child link="link_1_s"/>
    <origin rpy="0 0 0" xyz="0 0 0.505"/>
    <axis xyz="0 0 1"/>
    <limit effort="3087" lower="-3.14159265359" upper="3.14159265359" velocity="3.66519142919"/>
  </joint>
  <joint name="joint_2_l" type="revolute">
    <parent link="link_1_s"/>
    <child link="link_2_l"/>
    <origin rpy="0 0 0" xyz="0.150 0 0"/>
    <axis xyz="0 1 0"/>
    <limit effort="3087" lower="-1.83259571459" upper="2.70526034059" velocity="3.66519142919"/>
  </joint>
  <joint name="joint_3_u" type="revolute">
    <parent link="link_2_l"/>
    <child link="link_3_u"/>
    <origin rpy="0 0 0" xyz="0 0 0.760"/>
    <axis xyz="0 -1 0"/>
    <limit effort="926.1" lower="-1.50098315672" upper="2.79252680319" velocity="4.62512251778"/>
  </joint>
  <joint name="joint_4_r" type="revolute">
    <parent link="link_3_u"/>
    <child link="link_4_r"/>
    <origin rpy="0 0 0" xyz="0 0 0.200"/>
    <axis xyz="-1 0 0"/>
    <limit effort="88.2" lower="-3.49065850399" upper="3.49065850399" velocity="7.33038285838"/>
  </joint>
  <joint name="joint_5_b" type="revolute">
    <parent link="link_4_r"/>
    <child link="link_5_b"/>
    <origin rpy="0 0 0" xyz="0.795 0 0"/>
    <axis xyz="0 -1 0"/>
    <limit effort="70.56" lower="-2.70526034059" upper="2.61799387799" velocity="7.33038285838"/>
  </joint>
  <joint name="joint_6_t" type="revolute">
    <parent link="link_5_b"/>
    <child link="link_6_t"/>
    <origin rpy="0 0 0" xyz="0 0 0"/>
    <axis xyz="-1 0 0"/>
    <limit effort="50.31" lower="-7.94124809657" upper="7.94124809657" velocity="15.4461638801"/>
  </joint>
  <joint name="joint_6_t-tool0" type="fixed">
    <origin rpy="3.1415926 -1.570796 0" xyz="0.100 0 0"/>
    <parent link="link_6_t"/>
    <child link="tool0"/>
  </joint>
  <!-- end of joint list -->
  <!-- ROS base_link to Robot Manufacturer World Coordinates transform -->
  <link name="base"/>
  <joint name="base_link-base" type="fixed">
    <origin rpy="0 0 0" xyz="0 0 0.505"/>
    <parent link="base_link"/>
    <child link="base"/>
  </joint>

  <ros2_control name="MotomanHardware" type="system">
    <hardware>
      <plugin>motoman_hardware/MotomanHardware</plugin>
      <param name="example_param_hw_start_duration_sec">2.0</param>
      <param name="example_param_hw_stop_duration_sec">3.0</param>
      <param name="example_param_hw_slowdown">2.0</param>
    </hardware>
    <joint name="joint_1_s">
      <command_interface name="position">
        <param name="min">-1</param>
        <param name="max">1</param>
      </command_interface>
      <state_interface name="position"/>
    </joint>
    <joint name="joint_2_l">
      <command_interface name="position">
        <param name="min">-1</param>
        <param name="max">1</param>
      </command_interface>
      <state_interface name="position"/>
    </joint>
    <joint name="joint_3_u">
      <command_interface name="position">
        <param name="min">-1</param>
        <param name="max">1</param>
      </command_interface>
      <state_interface name="position"/>
    </joint>
    <joint name="joint_4_r">
      <command_interface name="position">
        <param name="min">-1</param>
        <param name="max">1</param>
      </command_interface>
      <state_interface name="position"/>
    </joint>
    <joint name="joint_5_b">
      <command_interface name="position">
        <param name="min">-1</param>
        <param name="max">1</param>
      </command_interface>
      <state_interface name="position"/>
    </joint>
    <joint name="joint_6_t">
      <command_interface name="position">
        <param name="min">-1</param>
        <param name="max">1</param>
      </command_interface>
      <state_interface name="position"/>
    </joint>
  </ros2_control>
</robot>
